<?xml version='1.0'?>
<sdf version="1.4">
<model name="lever">
    <link name="base">
      <pose>0 0 0 0 0 0</pose>
      <inertial>
        <mass>0.5</mass>
        <inertia> <!-- inertias are tricky to compute -->
          <!-- http://answers.gazebosim.org/question/4372/the-inertia-matrix-explained/ -->
          <ixx>0.008</ixx>       <!-- for a box: ixx = 0.083 * mass * (y*y + z*z) -->
          <ixy>0.0</ixy>         <!-- for a box: ixy = 0 -->
          <ixz>0.0</ixz>         <!-- for a box: ixz = 0 -->
          <iyy>0.008</iyy>       <!-- for a box: iyy = 0.083 * mass * (x*x + z*z) -->
          <iyz>0.0</iyz>         <!-- for a box: iyz = 0 -->
          <izz>0.083</izz>       <!-- for a box: izz = 0.083 * mass * (x*x + y*y) -->
        </inertia>
      </inertial>
      <collision name="collision">
        <geometry>
            <mesh>
                <uri>model://lever/meshes/base.dae</uri>
            </mesh>
        </geometry>
      </collision>
      <visual name="visual">
        <geometry>
            <mesh>
                <uri>model://lever/meshes/base.dae</uri>
            </mesh>
        </geometry>
      </visual>
    </link>

    <link name="lever">
      <pose>0 0 0.015 0 0 0</pose>
      <inertial>
        <mass>0.5</mass>
        <pose>0 0 0.035 0 0 0</pose>
        <inertia> <!-- inertias are tricky to compute -->
          <!-- http://answers.gazebosim.org/question/4372/the-inertia-matrix-explained/ -->
          <ixx>0.008</ixx>       <!-- for a box: ixx = 0.083 * mass * (y*y + z*z) -->
          <ixy>0.0</ixy>         <!-- for a box: ixy = 0 -->
          <ixz>0.0</ixz>         <!-- for a box: ixz = 0 -->
          <iyy>0.083</iyy>       <!-- for a box: iyy = 0.083 * mass * (x*x + z*z) -->
          <iyz>0.0</iyz>         <!-- for a box: iyz = 0 -->
          <izz>0.008</izz>       <!-- for a box: izz = 0.083 * mass * (x*x + y*y) -->
        </inertia>
      </inertial>
      <collision name="collision">
        <geometry>
            <mesh>
                <uri>model://lever/meshes/lever.dae</uri>
            </mesh>
        </geometry>
      </collision>
      <visual name="visual">
        <geometry>
            <mesh>
                <uri>model://lever/meshes/lever.dae</uri>
            </mesh>
        </geometry>
      </visual>
    </link>

    <joint name="pivot" type="revolute">
        <pose>0 0 0 0 0 0</pose>
        <child>lever</child>
        <parent>base</parent>
        <axis>
            <xyz>1 0 0</xyz>
            <limit>
                <lower>-0.8</lower>
                <upper>0.8</upper>
            </limit>
        </axis>
    </joint>

    <plugin name="sensor" filename="/home/masson/gazebo/models/lever/plugins/build/libsensor.so"/>

  </model>
</sdf>
