<?xml version='1.0'?>
<sdf version="1.4">
<model name="lever">
    <link name="base">
      <pose>0 0 0 0 0 0</pose>
      <inertial>
        <mass>0.5</mass>
        <inertia>
          <ixx>0.0008</ixx>
          <ixy>0.0</ixy>
          <ixz>0.0</ixz>
          <iyy>0.0008</iyy>
          <iyz>0.0</iyz>
          <izz>0.0083</izz>
        </inertia>
      </inertial>
      <collision name="collision">
        <geometry>
            <mesh>
                <uri>model://DREAM_lever/meshes/base.dae</uri>
            </mesh>
        </geometry>
      </collision>
      <visual name="visual">
        <geometry>
            <mesh>
                <uri>model://DREAM_lever/meshes/base.dae</uri>
            </mesh>
        </geometry>
      </visual>
    </link>

    <link name="lever">
      <pose>0 0 0.015 0 0 0</pose>
      <inertial>
        <mass>0.2</mass>
        <pose>0 0 0.035 0 0 0</pose>
        <inertia>
          <ixx>0.0008</ixx>
          <ixy>0.0</ixy>
          <ixz>0.0</ixz>
          <iyy>0.0083</iyy>
          <iyz>0.0</iyz>
          <izz>0.0008</izz>
        </inertia>
      </inertial>
      <collision name="collision">
        <geometry>
            <mesh>
                <uri>model://DREAM_lever/meshes/lever.dae</uri>
            </mesh>
        </geometry>
      </collision>
      <visual name="visual">
        <geometry>
            <mesh>
                <uri>model://DREAM_lever/meshes/lever.dae</uri>
            </mesh>
        </geometry>
      </visual>
    </link>

    <joint name="pivot" type="revolute">
        <pose>0 0 0 0 0 0</pose>
        <child>lever</child>
        <parent>base</parent>
        <axis>
            <xyz>1 0 0</xyz>
            <limit>
                <lower>-0.8</lower>
                <upper>0.8</upper>
            </limit>
        </axis>
    </joint>

    <plugin name="sensor" filename="libDREAM_lever_sensor.so"/>

  </model>
</sdf>
